{
 "cells": [
  {
   "cell_type": "code",
   "execution_count": 51,
   "metadata": {},
   "outputs": [],
   "source": [
    "import numpy as np\n",
    "import tensorflow as tf\n",
    "import keras\n",
    "from tensorflow.keras.layers import Conv1D, Dense, Dropout, MaxPooling1D\n",
    "from tensorflow.keras.models import Sequential, Model"
   ]
  },
  {
   "cell_type": "code",
   "execution_count": 52,
   "metadata": {},
   "outputs": [],
   "source": [
    "X_train = np.load(\"../X_train.npy\")\n",
    "y_train = np.load(\"../y_train.npy\")\n",
    "X_test = np.load(\"../X_test.npy\")\n",
    "y_test = np.load(\"../y_test.npy\")"
   ]
  },
  {
   "cell_type": "code",
   "execution_count": 53,
   "metadata": {},
   "outputs": [
    {
     "data": {
      "text/plain": [
       "((8624, 5, 19), (8624,), (3696, 5, 19), (3696,))"
      ]
     },
     "execution_count": 53,
     "metadata": {},
     "output_type": "execute_result"
    }
   ],
   "source": [
    "X_train.shape, y_train.shape, X_test.shape, y_test.shape"
   ]
  },
  {
   "cell_type": "code",
   "execution_count": 54,
   "metadata": {},
   "outputs": [
    {
     "data": {
      "text/plain": [
       "((8624, 5, 19), (8624, 1), (3696, 5, 19), (3696, 1))"
      ]
     },
     "execution_count": 54,
     "metadata": {},
     "output_type": "execute_result"
    }
   ],
   "source": [
    "y_train = y_train.reshape((-1,1))\n",
    "y_test = y_test.reshape((-1,1))\n",
    "X_train.shape, y_train.shape, X_test.shape, y_test.shape"
   ]
  },
  {
   "cell_type": "code",
   "execution_count": 55,
   "metadata": {},
   "outputs": [],
   "source": [
    "model = Sequential()\n",
    "model.add(Conv1D(filters=16, kernel_size=2, padding='same', activation='elu', input_shape=(5, 19)))\n",
    "model.add(Conv1D(filters=16, kernel_size=2, padding='same', activation='elu'))\n",
    "model.add(MaxPooling1D(pool_size=2))\n",
    "model.add(Dropout(0.3))\n",
    "model.add(Conv1D(filters=32, kernel_size=2, padding='same', activation='elu'))\n",
    "model.add(Conv1D(filters=32, kernel_size=2, padding='same', activation='elu'))\n",
    "model.add(MaxPooling1D(pool_size=2))\n",
    "model.add(Dropout(0.3))\n",
    "model.add(Dense(128, activation='elu'))\n",
    "model.add(Dropout(0.5))\n",
    "model.add(Dense(1, activation='softmax'))\n",
    "model.compile(loss='binary_crossentropy', optimizer='adam', metrics=['accuracy'])\n",
    "model.save(\"cnn.h5\")"
   ]
  },
  {
   "cell_type": "code",
   "execution_count": 57,
   "metadata": {},
   "outputs": [
    {
     "name": "stdout",
     "output_type": "stream",
     "text": [
      "Epoch 1/10\n"
     ]
    },
    {
     "name": "stderr",
     "output_type": "stream",
     "text": [
      "2023-05-30 07:45:23.825431: E tensorflow/compiler/xla/stream_executor/cuda/cuda_dnn.cc:429] Could not create cudnn handle: CUDNN_STATUS_INTERNAL_ERROR\n",
      "2023-05-30 07:45:23.825472: W tensorflow/core/framework/op_kernel.cc:1830] OP_REQUIRES failed at conv_ops.cc:1068 : UNIMPLEMENTED: DNN library is not found.\n",
      "2023-05-30 07:45:23.825487: I tensorflow/core/common_runtime/executor.cc:1197] [/job:localhost/replica:0/task:0/device:GPU:0] (DEBUG INFO) Executor start aborting (this does not indicate an error and you can ignore this message): UNIMPLEMENTED: DNN library is not found.\n",
      "\t [[{{node sequential_7/conv1d_24/Conv1D}}]]\n"
     ]
    },
    {
     "ename": "UnimplementedError",
     "evalue": "Graph execution error:\n\nDetected at node 'sequential_7/conv1d_24/Conv1D' defined at (most recent call last):\n    File \"/usr/lib/python3.10/runpy.py\", line 196, in _run_module_as_main\n      return _run_code(code, main_globals, None,\n    File \"/usr/lib/python3.10/runpy.py\", line 86, in _run_code\n      exec(code, run_globals)\n    File \"/home/meliha/.local/lib/python3.10/site-packages/ipykernel_launcher.py\", line 17, in <module>\n      app.launch_new_instance()\n    File \"/home/meliha/.local/lib/python3.10/site-packages/traitlets/config/application.py\", line 1043, in launch_instance\n      app.start()\n    File \"/home/meliha/.local/lib/python3.10/site-packages/ipykernel/kernelapp.py\", line 725, in start\n      self.io_loop.start()\n    File \"/home/meliha/.local/lib/python3.10/site-packages/tornado/platform/asyncio.py\", line 195, in start\n      self.asyncio_loop.run_forever()\n    File \"/usr/lib/python3.10/asyncio/base_events.py\", line 600, in run_forever\n      self._run_once()\n    File \"/usr/lib/python3.10/asyncio/base_events.py\", line 1896, in _run_once\n      handle._run()\n    File \"/usr/lib/python3.10/asyncio/events.py\", line 80, in _run\n      self._context.run(self._callback, *self._args)\n    File \"/home/meliha/.local/lib/python3.10/site-packages/ipykernel/kernelbase.py\", line 513, in dispatch_queue\n      await self.process_one()\n    File \"/home/meliha/.local/lib/python3.10/site-packages/ipykernel/kernelbase.py\", line 502, in process_one\n      await dispatch(*args)\n    File \"/home/meliha/.local/lib/python3.10/site-packages/ipykernel/kernelbase.py\", line 409, in dispatch_shell\n      await result\n    File \"/home/meliha/.local/lib/python3.10/site-packages/ipykernel/kernelbase.py\", line 729, in execute_request\n      reply_content = await reply_content\n    File \"/home/meliha/.local/lib/python3.10/site-packages/ipykernel/ipkernel.py\", line 422, in do_execute\n      res = shell.run_cell(\n    File \"/home/meliha/.local/lib/python3.10/site-packages/ipykernel/zmqshell.py\", line 540, in run_cell\n      return super().run_cell(*args, **kwargs)\n    File \"/home/meliha/.local/lib/python3.10/site-packages/IPython/core/interactiveshell.py\", line 3009, in run_cell\n      result = self._run_cell(\n    File \"/home/meliha/.local/lib/python3.10/site-packages/IPython/core/interactiveshell.py\", line 3064, in _run_cell\n      result = runner(coro)\n    File \"/home/meliha/.local/lib/python3.10/site-packages/IPython/core/async_helpers.py\", line 129, in _pseudo_sync_runner\n      coro.send(None)\n    File \"/home/meliha/.local/lib/python3.10/site-packages/IPython/core/interactiveshell.py\", line 3269, in run_cell_async\n      has_raised = await self.run_ast_nodes(code_ast.body, cell_name,\n    File \"/home/meliha/.local/lib/python3.10/site-packages/IPython/core/interactiveshell.py\", line 3448, in run_ast_nodes\n      if await self.run_code(code, result, async_=asy):\n    File \"/home/meliha/.local/lib/python3.10/site-packages/IPython/core/interactiveshell.py\", line 3508, in run_code\n      exec(code_obj, self.user_global_ns, self.user_ns)\n    File \"/tmp/ipykernel_57043/4228168276.py\", line 1, in <module>\n      history = model.fit(X_train, y_train, epochs=10, validation_data=(X_train, y_test), verbose=1)\n    File \"/home/meliha/.local/lib/python3.10/site-packages/keras/utils/traceback_utils.py\", line 65, in error_handler\n      return fn(*args, **kwargs)\n    File \"/home/meliha/.local/lib/python3.10/site-packages/keras/engine/training.py\", line 1685, in fit\n      Args:\n    File \"/home/meliha/.local/lib/python3.10/site-packages/keras/engine/training.py\", line 1284, in train_function\n      `epochs` is to be understood as \"final epoch\".\n    File \"/home/meliha/.local/lib/python3.10/site-packages/keras/engine/training.py\", line 1268, in step_function\n      It should be consistent with `x` (you cannot have Numpy inputs and\n    File \"/home/meliha/.local/lib/python3.10/site-packages/keras/engine/training.py\", line 1249, in run_step\n      `(inputs, targets, sample_weights)`.\n    File \"/home/meliha/.local/lib/python3.10/site-packages/keras/engine/training.py\", line 1050, in train_step\n      \"\"\"\n    File \"/home/meliha/.local/lib/python3.10/site-packages/keras/utils/traceback_utils.py\", line 65, in error_handler\n      return fn(*args, **kwargs)\n    File \"/home/meliha/.local/lib/python3.10/site-packages/keras/engine/training.py\", line 558, in __call__\n    File \"/home/meliha/.local/lib/python3.10/site-packages/keras/utils/traceback_utils.py\", line 65, in error_handler\n      return fn(*args, **kwargs)\n    File \"/home/meliha/.local/lib/python3.10/site-packages/keras/engine/base_layer.py\", line 1145, in __call__\n      \"\"\"Name of the layer (string), set in the constructor.\"\"\"\n    File \"/home/meliha/.local/lib/python3.10/site-packages/keras/utils/traceback_utils.py\", line 96, in error_handler\n      return fn(*args, **kwargs)\n    File \"/home/meliha/.local/lib/python3.10/site-packages/keras/engine/sequential.py\", line 412, in call\n      outputs = inputs  # handle the corner case where self.layers is empty\n    File \"/home/meliha/.local/lib/python3.10/site-packages/keras/engine/functional.py\", line 512, in call\n      def compute_output_shape(self, input_shape):\n    File \"/home/meliha/.local/lib/python3.10/site-packages/keras/engine/functional.py\", line 669, in _run_internal_graph\n      # Update tensor_dict.\n    File \"/home/meliha/.local/lib/python3.10/site-packages/keras/utils/traceback_utils.py\", line 65, in error_handler\n      return fn(*args, **kwargs)\n    File \"/home/meliha/.local/lib/python3.10/site-packages/keras/engine/base_layer.py\", line 1145, in __call__\n      \"\"\"Name of the layer (string), set in the constructor.\"\"\"\n    File \"/home/meliha/.local/lib/python3.10/site-packages/keras/utils/traceback_utils.py\", line 96, in error_handler\n      return fn(*args, **kwargs)\n    File \"/home/meliha/.local/lib/python3.10/site-packages/keras/layers/convolutional/base_conv.py\", line 290, in call\n      outputs += bias\n    File \"/home/meliha/.local/lib/python3.10/site-packages/keras/layers/convolutional/base_conv.py\", line 262, in convolution_op\n      name=self.__class__.__name__,\nNode: 'sequential_7/conv1d_24/Conv1D'\nDNN library is not found.\n\t [[{{node sequential_7/conv1d_24/Conv1D}}]] [Op:__inference_train_function_5984]",
     "output_type": "error",
     "traceback": [
      "\u001b[0;31m---------------------------------------------------------------------------\u001b[0m",
      "\u001b[0;31mUnimplementedError\u001b[0m                        Traceback (most recent call last)",
      "Cell \u001b[0;32mIn[57], line 1\u001b[0m\n\u001b[0;32m----> 1\u001b[0m history \u001b[39m=\u001b[39m model\u001b[39m.\u001b[39;49mfit(X_train, y_train, epochs\u001b[39m=\u001b[39;49m\u001b[39m10\u001b[39;49m, validation_data\u001b[39m=\u001b[39;49m(X_train, y_test), verbose\u001b[39m=\u001b[39;49m\u001b[39m1\u001b[39;49m)\n",
      "File \u001b[0;32m~/.local/lib/python3.10/site-packages/keras/utils/traceback_utils.py:70\u001b[0m, in \u001b[0;36mfilter_traceback.<locals>.error_handler\u001b[0;34m(*args, **kwargs)\u001b[0m\n\u001b[1;32m     67\u001b[0m     filtered_tb \u001b[39m=\u001b[39m _process_traceback_frames(e\u001b[39m.\u001b[39m__traceback__)\n\u001b[1;32m     68\u001b[0m     \u001b[39m# To get the full stack trace, call:\u001b[39;00m\n\u001b[1;32m     69\u001b[0m     \u001b[39m# `tf.debugging.disable_traceback_filtering()`\u001b[39;00m\n\u001b[0;32m---> 70\u001b[0m     \u001b[39mraise\u001b[39;00m e\u001b[39m.\u001b[39mwith_traceback(filtered_tb) \u001b[39mfrom\u001b[39;00m \u001b[39mNone\u001b[39;00m\n\u001b[1;32m     71\u001b[0m \u001b[39mfinally\u001b[39;00m:\n\u001b[1;32m     72\u001b[0m     \u001b[39mdel\u001b[39;00m filtered_tb\n",
      "File \u001b[0;32m~/.local/lib/python3.10/site-packages/tensorflow/python/eager/execute.py:52\u001b[0m, in \u001b[0;36mquick_execute\u001b[0;34m(op_name, num_outputs, inputs, attrs, ctx, name)\u001b[0m\n\u001b[1;32m     50\u001b[0m \u001b[39mtry\u001b[39;00m:\n\u001b[1;32m     51\u001b[0m   ctx\u001b[39m.\u001b[39mensure_initialized()\n\u001b[0;32m---> 52\u001b[0m   tensors \u001b[39m=\u001b[39m pywrap_tfe\u001b[39m.\u001b[39mTFE_Py_Execute(ctx\u001b[39m.\u001b[39m_handle, device_name, op_name,\n\u001b[1;32m     53\u001b[0m                                       inputs, attrs, num_outputs)\n\u001b[1;32m     54\u001b[0m \u001b[39mexcept\u001b[39;00m core\u001b[39m.\u001b[39m_NotOkStatusException \u001b[39mas\u001b[39;00m e:\n\u001b[1;32m     55\u001b[0m   \u001b[39mif\u001b[39;00m name \u001b[39mis\u001b[39;00m \u001b[39mnot\u001b[39;00m \u001b[39mNone\u001b[39;00m:\n",
      "\u001b[0;31mUnimplementedError\u001b[0m: Graph execution error:\n\nDetected at node 'sequential_7/conv1d_24/Conv1D' defined at (most recent call last):\n    File \"/usr/lib/python3.10/runpy.py\", line 196, in _run_module_as_main\n      return _run_code(code, main_globals, None,\n    File \"/usr/lib/python3.10/runpy.py\", line 86, in _run_code\n      exec(code, run_globals)\n    File \"/home/meliha/.local/lib/python3.10/site-packages/ipykernel_launcher.py\", line 17, in <module>\n      app.launch_new_instance()\n    File \"/home/meliha/.local/lib/python3.10/site-packages/traitlets/config/application.py\", line 1043, in launch_instance\n      app.start()\n    File \"/home/meliha/.local/lib/python3.10/site-packages/ipykernel/kernelapp.py\", line 725, in start\n      self.io_loop.start()\n    File \"/home/meliha/.local/lib/python3.10/site-packages/tornado/platform/asyncio.py\", line 195, in start\n      self.asyncio_loop.run_forever()\n    File \"/usr/lib/python3.10/asyncio/base_events.py\", line 600, in run_forever\n      self._run_once()\n    File \"/usr/lib/python3.10/asyncio/base_events.py\", line 1896, in _run_once\n      handle._run()\n    File \"/usr/lib/python3.10/asyncio/events.py\", line 80, in _run\n      self._context.run(self._callback, *self._args)\n    File \"/home/meliha/.local/lib/python3.10/site-packages/ipykernel/kernelbase.py\", line 513, in dispatch_queue\n      await self.process_one()\n    File \"/home/meliha/.local/lib/python3.10/site-packages/ipykernel/kernelbase.py\", line 502, in process_one\n      await dispatch(*args)\n    File \"/home/meliha/.local/lib/python3.10/site-packages/ipykernel/kernelbase.py\", line 409, in dispatch_shell\n      await result\n    File \"/home/meliha/.local/lib/python3.10/site-packages/ipykernel/kernelbase.py\", line 729, in execute_request\n      reply_content = await reply_content\n    File \"/home/meliha/.local/lib/python3.10/site-packages/ipykernel/ipkernel.py\", line 422, in do_execute\n      res = shell.run_cell(\n    File \"/home/meliha/.local/lib/python3.10/site-packages/ipykernel/zmqshell.py\", line 540, in run_cell\n      return super().run_cell(*args, **kwargs)\n    File \"/home/meliha/.local/lib/python3.10/site-packages/IPython/core/interactiveshell.py\", line 3009, in run_cell\n      result = self._run_cell(\n    File \"/home/meliha/.local/lib/python3.10/site-packages/IPython/core/interactiveshell.py\", line 3064, in _run_cell\n      result = runner(coro)\n    File \"/home/meliha/.local/lib/python3.10/site-packages/IPython/core/async_helpers.py\", line 129, in _pseudo_sync_runner\n      coro.send(None)\n    File \"/home/meliha/.local/lib/python3.10/site-packages/IPython/core/interactiveshell.py\", line 3269, in run_cell_async\n      has_raised = await self.run_ast_nodes(code_ast.body, cell_name,\n    File \"/home/meliha/.local/lib/python3.10/site-packages/IPython/core/interactiveshell.py\", line 3448, in run_ast_nodes\n      if await self.run_code(code, result, async_=asy):\n    File \"/home/meliha/.local/lib/python3.10/site-packages/IPython/core/interactiveshell.py\", line 3508, in run_code\n      exec(code_obj, self.user_global_ns, self.user_ns)\n    File \"/tmp/ipykernel_57043/4228168276.py\", line 1, in <module>\n      history = model.fit(X_train, y_train, epochs=10, validation_data=(X_train, y_test), verbose=1)\n    File \"/home/meliha/.local/lib/python3.10/site-packages/keras/utils/traceback_utils.py\", line 65, in error_handler\n      return fn(*args, **kwargs)\n    File \"/home/meliha/.local/lib/python3.10/site-packages/keras/engine/training.py\", line 1685, in fit\n      Args:\n    File \"/home/meliha/.local/lib/python3.10/site-packages/keras/engine/training.py\", line 1284, in train_function\n      `epochs` is to be understood as \"final epoch\".\n    File \"/home/meliha/.local/lib/python3.10/site-packages/keras/engine/training.py\", line 1268, in step_function\n      It should be consistent with `x` (you cannot have Numpy inputs and\n    File \"/home/meliha/.local/lib/python3.10/site-packages/keras/engine/training.py\", line 1249, in run_step\n      `(inputs, targets, sample_weights)`.\n    File \"/home/meliha/.local/lib/python3.10/site-packages/keras/engine/training.py\", line 1050, in train_step\n      \"\"\"\n    File \"/home/meliha/.local/lib/python3.10/site-packages/keras/utils/traceback_utils.py\", line 65, in error_handler\n      return fn(*args, **kwargs)\n    File \"/home/meliha/.local/lib/python3.10/site-packages/keras/engine/training.py\", line 558, in __call__\n    File \"/home/meliha/.local/lib/python3.10/site-packages/keras/utils/traceback_utils.py\", line 65, in error_handler\n      return fn(*args, **kwargs)\n    File \"/home/meliha/.local/lib/python3.10/site-packages/keras/engine/base_layer.py\", line 1145, in __call__\n      \"\"\"Name of the layer (string), set in the constructor.\"\"\"\n    File \"/home/meliha/.local/lib/python3.10/site-packages/keras/utils/traceback_utils.py\", line 96, in error_handler\n      return fn(*args, **kwargs)\n    File \"/home/meliha/.local/lib/python3.10/site-packages/keras/engine/sequential.py\", line 412, in call\n      outputs = inputs  # handle the corner case where self.layers is empty\n    File \"/home/meliha/.local/lib/python3.10/site-packages/keras/engine/functional.py\", line 512, in call\n      def compute_output_shape(self, input_shape):\n    File \"/home/meliha/.local/lib/python3.10/site-packages/keras/engine/functional.py\", line 669, in _run_internal_graph\n      # Update tensor_dict.\n    File \"/home/meliha/.local/lib/python3.10/site-packages/keras/utils/traceback_utils.py\", line 65, in error_handler\n      return fn(*args, **kwargs)\n    File \"/home/meliha/.local/lib/python3.10/site-packages/keras/engine/base_layer.py\", line 1145, in __call__\n      \"\"\"Name of the layer (string), set in the constructor.\"\"\"\n    File \"/home/meliha/.local/lib/python3.10/site-packages/keras/utils/traceback_utils.py\", line 96, in error_handler\n      return fn(*args, **kwargs)\n    File \"/home/meliha/.local/lib/python3.10/site-packages/keras/layers/convolutional/base_conv.py\", line 290, in call\n      outputs += bias\n    File \"/home/meliha/.local/lib/python3.10/site-packages/keras/layers/convolutional/base_conv.py\", line 262, in convolution_op\n      name=self.__class__.__name__,\nNode: 'sequential_7/conv1d_24/Conv1D'\nDNN library is not found.\n\t [[{{node sequential_7/conv1d_24/Conv1D}}]] [Op:__inference_train_function_5984]"
     ]
    }
   ],
   "source": [
    "history = model.fit(X_train, y_train, epochs=10, validation_data=(X_train, y_test), verbose=1)"
   ]
  }
 ],
 "metadata": {
  "kernelspec": {
   "display_name": "Python 3",
   "language": "python",
   "name": "python3"
  },
  "language_info": {
   "codemirror_mode": {
    "name": "ipython",
    "version": 3
   },
   "file_extension": ".py",
   "mimetype": "text/x-python",
   "name": "python",
   "nbconvert_exporter": "python",
   "pygments_lexer": "ipython3",
   "version": "3.10.6"
  },
  "orig_nbformat": 4
 },
 "nbformat": 4,
 "nbformat_minor": 2
}
